Workbook

Sheet التقويم
A1: تقويم محتوى مسكوب (90 يومًا)
A2: تاريخ بدء الخطة | B2: [أدخل التاريخ] | C2: أدخل تاريخًا حقيقيًا في الخلية B2 لتظهر التواريخ تلقائيًا
A3: رقم يوم الافتتاح (عدّله) | B3: 46
A5: اليوم | B5: التاريخ | C5: المرحلة | D5: الركيزة | E5: شكل إنستجرام | F5: الفكرة | G5: كابشن مسودة (بالمصري) | H5: الأصول المطلوبة | I5: الدعوة | J5: مؤشر النجاح | K5: ستوري | L5: فيسبوك | M5: خرائط جوجل | N5: واتساب (بموافقة فقط) | O5: الحالة
A6: 1 | B6: =IF(ISNUMBER($B$2),$B$2+A6-1,"") | C6: تشويق وهوية | D6: الحرفة | E6: ريل | F6: معنى الاسم: السكب | G6: سكبة واحدة بتفرق. اسمنا جاي من هنا. | H6: فيديو سكب قهوة (تصوير مبدئي) | I6: احفظ | J6: حفظ ومشاركة | K6: لقطة من الأفكار الأولى | L6: نشر الموضوع نفسه بنص محلي: معنى الاسم: السكب | O6: مسودة
A7: 2 | B7: =IF(ISNUMBER($B$2),$B$2+A7-1,"") | C7: تشويق وهوية | D7: الأجواء | E7: منشور | F7: ألوان المكان من خاماته | G7: الأزرق والخشب والرملي. ألوان مكاننا طالعة من خاماته. | H7: لوحة الألوان | I7: شاركنا رأيك | J7: تعليقات | K7: سؤال: قهوتك إزاي؟ | L7: نشر الموضوع نفسه بنص محلي: ألوان المكان من خاماته | O7: مسودة
A8: 3 | B8: =IF(ISNUMBER($B$2),$B$2+A8-1,"") | C8: تشويق وهوية | E8: ستوري فقط | K8: كلمة الأسبوع: سكب | O8: مسودة
A9: 4 | B9: =IF(ISNUMBER($B$2),$B$2+A9-1,"") | C9: تشويق وهوية | D9: الحرفة | E9: ريل | F9: معنى الاسم: السكب | G9: سكبة واحدة بتفرق. اسمنا جاي من هنا. | H9: فيديو سكب قهوة (تصوير مبدئي) | I9: احفظ | J9: حفظ ومشاركة | K9: لقطة من الأفكار الأولى | L9: نشر الموضوع نفسه بنص محلي: معنى الاسم: السكب | O9: مسودة
A10: 5 | B10: =IF(ISNUMBER($B$2),$B$2+A10-1,"") | C10: تشويق وهوية | D10: الأجواء | E10: كاروسيل | F10: من الفكرة للمكان | G10: من ورقة بسيطة لمكان بيتبني. ده أول فصل. | H10: 3 إلى 5 صور تصميم | I10: احفظ | J10: حفظ | K10: سؤال: قهوتك إزاي؟ | L10: نشر الموضوع نفسه بنص محلي: من الفكرة للمكان | O10: مسودة
A11: 6 | B11: =IF(ISNUMBER($B$2),$B$2+A11-1,"") | C11: تشويق وهوية | E11: ستوري فقط | K11: كلمة الأسبوع: سكب | M11: تحديث صور الملف | O11: مسودة
A12: 7 | B12: =IF(ISNUMBER($B$2),$B$2+A12-1,"") | C12: تشويق وهوية | E12: راحة ومتابعة تفاعل | O12: مسودة
A13: 8 | B13: =IF(ISNUMBER($B$2),$B$2+A13-1,"") | C13: تشويق وهوية | D13: الحرفة | E13: ريل | F13: معنى الاسم: السكب | G13: سكبة واحدة بتفرق. اسمنا جاي من هنا. | H13: فيديو سكب قهوة (تصوير مبدئي) | I13: احفظ | J13: حفظ ومشاركة | K13: سؤال: قهوتك إزاي؟ | L13: نشر الموضوع نفسه بنص محلي: معنى الاسم: السكب | O13: مسودة
A14: 9 | B14: =IF(ISNUMBER($B$2),$B$2+A14-1,"") | C14: تشويق وهوية | D14: الأجواء | E14: منشور | F14: ألوان المكان من خاماته | G14: الأزرق والخشب والرملي. ألوان مكاننا طالعة من خاماته. | H14: لوحة الألوان | I14: شاركنا رأيك | J14: تعليقات | K14: كلمة الأسبوع: سكب | L14: نشر الموضوع نفسه بنص محلي: ألوان المكان من خاماته | O14: مسودة
A15: 10 | B15: =IF(ISNUMBER($B$2),$B$2+A15-1,"") | C15: تشويق وهوية | E15: ستوري فقط | K15: لقطة من الأفكار الأولى | O15: مسودة
A16: 11 | B16: =IF(ISNUMBER($B$2),$B$2+A16-1,"") | C16: تشويق وهوية | D16: الحرفة | E16: ريل | F16: معنى الاسم: السكب | G16: سكبة واحدة بتفرق. اسمنا جاي من هنا. | H16: فيديو سكب قهوة (تصوير مبدئي) | I16: احفظ | J16: حفظ ومشاركة | K16: سؤال: قهوتك إزاي؟ | L16: نشر الموضوع نفسه بنص محلي: معنى الاسم: السكب | O16: مسودة
A17: 12 | B17: =IF(ISNUMBER($B$2),$B$2+A17-1,"") | C17: تشويق وهوية | D17: الأجواء | E17: كاروسيل | F17: من الفكرة للمكان | G17: من ورقة بسيطة لمكان بيتبني. ده أول فصل. | H17: 3 إلى 5 صور تصميم | I17: احفظ | J17: حفظ | K17: كلمة الأسبوع: سكب | L17: نشر الموضوع نفسه بنص محلي: من الفكرة للمكان | O17: مسودة
A18: 13 | B18: =IF(ISNUMBER($B$2),$B$2+A18-1,"") | C18: تشويق وهوية | E18: ستوري فقط | K18: لقطة من الأفكار الأولى | M18: منشور على الملف: [عرض/حدث] | O18: مسودة
A19: 14 | B19: =IF(ISNUMBER($B$2),$B$2+A19-1,"") | C19: تشويق وهوية | E19: راحة ومتابعة تفاعل | O19: مسودة
A20: 15 | B20: =IF(ISNUMBER($B$2),$B$2+A20-1,"") | C20: كواليس المكان والقهوة | D20: الأجواء | E20: ريل | F20: تقدم التشطيب في المكان | G20: المكان بيكبر يوم عن يوم. | H20: لقطات الموقع | I20: تابعنا | J20: مشاهدات | K20: لقطة من الموقع | L20: نشر الموضوع نفسه بنص محلي: تقدم التشطيب في المكان | O20: مسودة
A21: 16 | B21: =IF(ISNUMBER($B$2),$B$2+A21-1,"") | C21: كواليس المكان والقهوة | D21: المنتجات | E21: منشور | F21: لمحة عن الحلويات والمخبوزات [المنيو مطلوب] | G21: حاجة حلوة مع قهوتك. لسه بنظبط التفاصيل. | H21: صور المنتج الحقيقية | I21: احفظ | J21: حفظ | K21: وراء الكواليس: [شيء جديد] | L21: نشر الموضوع نفسه بنص محلي: لمحة عن الحلويات والمخبوزات [المنيو مطلوب] | O21: مسودة
A22: 17 | B22: =IF(ISNUMBER($B$2),$B$2+A22-1,"") | C22: كواليس المكان والقهوة | E22: ستوري فقط | K22: استطلاع رأي صغير | O22: مسودة
A23: 18 | B23: =IF(ISNUMBER($B$2),$B$2+A23-1,"") | C23: كواليس المكان والقهوة | D23: الناس والمجتمع | E23: ريل | F23: تعرّف على الفريق | G23: الناس اللي هتقابلوهم أول ما تدخلوا. | H23: تصوير الفريق مع موافقتهم | I23: تابعنا | J23: مشاهدات | K23: سؤال وجواب عن القهوة | L23: نشر الموضوع نفسه بنص محلي: تعرّف على الفريق | O23: مسودة
A24: 19 | B24: =IF(ISNUMBER($B$2),$B$2+A24-1,"") | C24: كواليس المكان والقهوة | D24: العروض | E24: منشور | F24: كلمة على الجيران والمكاتب القريبة | G24: جيراننا في العاشر، قربنا. هنعدّي عليكم. | H24: تصميم | I24: تواصل واتساب | J24: رسائل | K24: لقطة من الموقع | L24: نشر الموضوع نفسه بنص محلي: كلمة على الجيران والمكاتب القريبة | O24: مسودة
A25: 20 | B25: =IF(ISNUMBER($B$2),$B$2+A25-1,"") | C25: كواليس المكان والقهوة | E25: ستوري فقط | K25: وراء الكواليس: [شيء جديد] | M25: طلب مراجعة بعد الزيارة | O25: مسودة
A26: 21 | B26: =IF(ISNUMBER($B$2),$B$2+A26-1,"") | C26: كواليس المكان والقهوة | E26: راحة ومتابعة تفاعل | O26: مسودة
A27: 22 | B27: =IF(ISNUMBER($B$2),$B$2+A27-1,"") | C27: كواليس المكان والقهوة | D27: الأجواء | E27: ريل | F27: تقدم التشطيب في المكان | G27: المكان بيكبر يوم عن يوم. | H27: لقطات الموقع | I27: تابعنا | J27: مشاهدات | K27: سؤال وجواب عن القهوة | L27: نشر الموضوع نفسه بنص محلي: تقدم التشطيب في المكان | O27: مسودة
A28: 23 | B28: =IF(ISNUMBER($B$2),$B$2+A28-1,"") | C28: كواليس المكان والقهوة | D28: المنتجات | E28: منشور | F28: لمحة عن الحلويات والمخبوزات [المنيو مطلوب] | G28: حاجة حلوة مع قهوتك. لسه بنظبط التفاصيل. | H28: صور المنتج الحقيقية | I28: احفظ | J28: حفظ | K28: لقطة من الموقع | L28: نشر الموضوع نفسه بنص محلي: لمحة عن الحلويات والمخبوزات [المنيو مطلوب] | O28: مسودة
A29: 24 | B29: =IF(ISNUMBER($B$2),$B$2+A29-1,"") | C29: كواليس المكان والقهوة | E29: ستوري فقط | K29: وراء الكواليس: [شيء جديد] | O29: مسودة
A30: 25 | B30: =IF(ISNUMBER($B$2),$B$2+A30-1,"") | C30: كواليس المكان والقهوة | D30: الناس والمجتمع | E30: ريل | F30: تعرّف على الفريق | G30: الناس اللي هتقابلوهم أول ما تدخلوا. | H30: تصوير الفريق مع موافقتهم | I30: تابعنا | J30: مشاهدات | K30: استطلاع رأي صغير | L30: نشر الموضوع نفسه بنص محلي: تعرّف على الفريق | O30: مسودة
A31: 26 | B31: =IF(ISNUMBER($B$2),$B$2+A31-1,"") | C31: كواليس المكان والقهوة | D31: العروض | E31: منشور | F31: كلمة على الجيران والمكاتب القريبة | G31: جيراننا في العاشر، قربنا. هنعدّي عليكم. | H31: تصميم | I31: تواصل واتساب | J31: رسائل | K31: سؤال وجواب عن القهوة | L31: نشر الموضوع نفسه بنص محلي: كلمة على الجيران والمكاتب القريبة | O31: مسودة
A32: 27 | B32: =IF(ISNUMBER($B$2),$B$2+A32-1,"") | C32: كواليس المكان والقهوة | E32: ستوري فقط | K32: لقطة من الموقع | M32: إضافة صور المنتج | O32: مسودة
A33: 28 | B33: =IF(ISNUMBER($B$2),$B$2+A33-1,"") | C33: كواليس المكان والقهوة | E33: راحة ومتابعة تفاعل | O33: مسودة
A34: 29 | B34: =IF(ISNUMBER($B$2),$B$2+A34-1,"") | C34: كواليس المكان والقهوة | D34: الأجواء | E34: ريل | F34: تقدم التشطيب في المكان | G34: المكان بيكبر يوم عن يوم. | H34: لقطات الموقع | I34: تابعنا | J34: مشاهدات | K34: استطلاع رأي صغير | L34: نشر الموضوع نفسه بنص محلي: تقدم التشطيب في المكان | O34: مسودة
A35: 30 | B35: =IF(ISNUMBER($B$2),$B$2+A35-1,"") | C35: كواليس المكان والقهوة | D35: المنتجات | E35: منشور | F35: لمحة عن الحلويات والمخبوزات [المنيو مطلوب] | G35: حاجة حلوة مع قهوتك. لسه بنظبط التفاصيل. | H35: صور المنتج الحقيقية | I35: احفظ | J35: حفظ | K35: سؤال وجواب عن القهوة | L35: نشر الموضوع نفسه بنص محلي: لمحة عن الحلويات والمخبوزات [المنيو مطلوب] | O35: مسودة
A36: 31 | B36: =IF(ISNUMBER($B$2),$B$2+A36-1,"") | C36: كواليس المكان والقهوة | E36: ستوري فقط | K36: لقطة من الموقع | O36: مسودة
A37: 32 | B37: =IF(ISNUMBER($B$2),$B$2+A37-1,"") | C37: كواليس المكان والقهوة | D37: الناس والمجتمع | E37: ريل | F37: تعرّف على الفريق | G37: الناس اللي هتقابلوهم أول ما تدخلوا. | H37: تصوير الفريق مع موافقتهم | I37: تابعنا | J37: مشاهدات | K37: وراء الكواليس: [شيء جديد] | L37: نشر الموضوع نفسه بنص محلي: تعرّف على الفريق | O37: مسودة
A38: 33 | B38: =IF(ISNUMBER($B$2),$B$2+A38-1,"") | C38: كواليس المكان والقهوة | D38: العروض | E38: منشور | F38: كلمة على الجيران والمكاتب القريبة | G38: جيراننا في العاشر، قربنا. هنعدّي عليكم. | H38: تصميم | I38: تواصل واتساب | J38: رسائل | K38: استطلاع رأي صغير | L38: نشر الموضوع نفسه بنص محلي: كلمة على الجيران والمكاتب القريبة | O38: مسودة
A39: 34 | B39: =IF(ISNUMBER($B$2),$B$2+A39-1,"") | C39: كواليس المكان والقهوة | E39: ستوري فقط | K39: سؤال وجواب عن القهوة | M39: تحديث المواعيد والمنيو | O39: مسودة
A40: 35 | B40: =IF(ISNUMBER($B$2),$B$2+A40-1,"") | C40: العد التنازلي والافتتاح التجريبي | E40: راحة ومتابعة تفاعل | O40: مسودة
A41: 36 | B41: =IF(ISNUMBER($B$2),$B$2+A41-1,"") | C41: العد التنازلي والافتتاح التجريبي | D41: العروض | E41: ريل | F41: العد التنازلي | G41: باقي [عدد] أيام على الافتتاح. | H41: تصميم عد تنازلي | I41: فعّل التذكير | J41: مشاهدات | K41: تذكير بالدعوة | L41: نشر الموضوع نفسه بنص محلي: العد التنازلي | O41: مسودة
...

Sheet ملخص
A1: عدّاد الأشكال والمنصات
A3: البند | B3: العدد
A4: ريلز | B4: =COUNTIF('التقويم'!E6:E95,"ريل")
A5: منشورات | B5: =COUNTIF('التقويم'!E6:E95,"منشور")
A6: كاروسيل | B6: =COUNTIF('التقويم'!E6:E95,"كاروسيل")
A7: أيام ستوري | B7: =COUNTIF('التقويم'!K6:K95,"?*")
A8: نشر فيسبوك | B8: =COUNTIF('التقويم'!L6:L95,"?*")
A9: منشورات خرائط | B9: =COUNTIF('التقويم'!M6:M95,"?*")
A10: رسائل واتساب | B10: =COUNTIF('التقويم'!N6:N95,"?*")
A11: معتمد أو منشور | B11: =COUNTIF('التقويم'!O6:O95,"معتمد")+COUNTIF('التقويم'!O6:O95,"منشور")

Sheet الركائز
A1: الركيزة | B1: الهدف | C1: الجمهور | D1: الأشكال | E1: أمثلة | F1: الأصول | G1: الدعوة | H1: المقياس
A2: المنتجات والمشروبات | B2: إظهار ما نقدمه | C2: الزوار المحتملون | D2: لقطات قريبة وريلز | E2: أول سكبة من مشروب البيت [مطلوب] | F2: تصوير حقيقي للمنتج | G2: احفظ وجرّب | H2: الحفظ والمشاركة
A3: الأجواء والمكان | B3: بناء الإحساس | C3: السكان وأصحاب الأعمال | D3: صور وفيديو قصير | E3: من الإنشاء إلى الخامات | F3: دخول الموقع | G3: تابع للافتتاح | H3: المتابعون والوصول
A4: الحرفة والجودة | B4: كسب الثقة | C4: عشاق القهوة | D4: ريلز عملية وكاروسيل | E4: ضبط الشوت | F4: وقت الباريستا | G4: اسأل في التعليقات | H4: التعليقات
A5: الناس والمجتمع | B5: الانتماء المحلي | C5: السكان والمكاتب | D5: فريق وجيران | E5: تعريف بالفريق | F5: موافقات مكتوبة | G5: تاج صاحبك | H5: الإشارات
A6: العروض والتحويل | B6: دفع الزيارة الأولى | C6: القريبون من الموقع | D6: ستوري وإعلانات وواتساب | E6: دعوة الافتتاح | F6: عرض مؤكد | G6: اتجاهات وواتساب | H6: نقرات الاتجاهات والزيارات

Sheet قائمة اللقطات
A1: # | B1: اليوم المقترح | C1: اللقطة | D1: النوع | E1: المسؤول | F1: الحالة
A2: 1 | B2: [حدد] | C2: المكان أثناء التشطيب (ثابت ومتحرك) | D2: فيديو وصور | E2: المصوّر | F2: لم تُصوَّر
A3: 2 | B3: [حدد] | C3: الخامات: تيرازو وخشب وأزرق | D3: صور قريبة | E3: المصوّر | F3: لم تُصوَّر
A4: 3 | B4: [حدد] | C4: الماكينة والطحّانة: تشغيل أول | D4: فيديو | E4: المصوّر | F4: لم تُصوَّر
A5: 4 | B5: [حدد] | C5: الباريستا: ضبط الشوت | D5: فيديو | E5: المصوّر | F5: لم تُصوَّر
A6: 5 | B6: [حدد] | C6: البن [المصدر مطلوب] | D6: صور | E6: المصوّر | F6: لم تُصوَّر
A7: 6 | B7: [حدد] | C7: الحلويات والمخبوزات [المنيو مطلوب] | D7: صور | E7: المصوّر | F7: لم تُصوَّر
A8: 7 | B8: [حدد] | C8: الفريق (بموافقة) | D8: صور وفيديو | E8: المصوّر | F8: لم تُصوَّر
A9: 8 | B9: [حدد] | C9: الواجهة والمدخل | D9: صور | E9: المصوّر | F9: لم تُصوَّر
A10: 9 | B10: [حدد] | C10: الجلسات المختلفة بالنهار | D10: صور واسعة | E10: المصوّر | F10: لم تُصوَّر
A11: 10 | B11: [حدد] | C11: الافتتاح التجريبي (بموافقة الحضور) | D11: فيديو | E11: فريق الفيديو | F11: لم تُصوَّر
A12: 11 | B12: [حدد] | C12: يوم الافتتاح | D12: فيديو وصور | E12: فريق الفيديو | F12: لم تُصوَّر
A13: 12 | B13: [حدد] | C13: أول أسبوع: زوار بموافقتهم | D13: فيديو | E13: فريق الفيديو | F13: لم تُصوَّر

Sheet بنك الكابشنز
A1: اليوم | B1: المرحلة | C1: الفكرة | D1: كابشن مسودة بالمصري | E1: الحالة
A2: 1 | B2: تشويق وهوية | C2: معنى الاسم: السكب | D2: سكبة واحدة بتفرق. اسمنا جاي من هنا. | E2: بانتظار مراجعة كاتب ناطق
A3: 2 | B3: تشويق وهوية | C3: ألوان المكان من خاماته | D3: الأزرق والخشب والرملي. ألوان مكاننا طالعة من خاماته. | E3: بانتظار مراجعة كاتب ناطق
A4: 4 | B4: تشويق وهوية | C4: معنى الاسم: السكب | D4: سكبة واحدة بتفرق. اسمنا جاي من هنا. | E4: بانتظار مراجعة كاتب ناطق
A5: 5 | B5: تشويق وهوية | C5: من الفكرة للمكان | D5: من ورقة بسيطة لمكان بيتبني. ده أول فصل. | E5: بانتظار مراجعة كاتب ناطق
A6: 8 | B6: تشويق وهوية | C6: معنى الاسم: السكب | D6: سكبة واحدة بتفرق. اسمنا جاي من هنا. | E6: بانتظار مراجعة كاتب ناطق
A7: 9 | B7: تشويق وهوية | C7: ألوان المكان من خاماته | D7: الأزرق والخشب والرملي. ألوان مكاننا طالعة من خاماته. | E7: بانتظار مراجعة كاتب ناطق
A8: 11 | B8: تشويق وهوية | C8: معنى الاسم: السكب | D8: سكبة واحدة بتفرق. اسمنا جاي من هنا. | E8: بانتظار مراجعة كاتب ناطق
A9: 12 | B9: تشويق وهوية | C9: من الفكرة للمكان | D9: من ورقة بسيطة لمكان بيتبني. ده أول فصل. | E9: بانتظار مراجعة كاتب ناطق
A10: 15 | B10: كواليس المكان والقهوة | C10: تقدم التشطيب في المكان | D10: المكان بيكبر يوم عن يوم. | E10: بانتظار مراجعة كاتب ناطق
A11: 16 | B11: كواليس المكان والقهوة | C11: لمحة عن الحلويات والمخبوزات [المنيو مطلوب] | D11: حاجة حلوة مع قهوتك. لسه بنظبط التفاصيل. | E11: بانتظار مراجعة كاتب ناطق
A12: 18 | B12: كواليس المكان والقهوة | C12: تعرّف على الفريق | D12: الناس اللي هتقابلوهم أول ما تدخلوا. | E12: بانتظار مراجعة كاتب ناطق
A13: 19 | B13: كواليس المكان والقهوة | C13: كلمة على الجيران والمكاتب القريبة | D13: جيراننا في العاشر، قربنا. هنعدّي عليكم. | E13: بانتظار مراجعة كاتب ناطق
... A54: 89 | B54: الاحتفاظ | C54: سلسلة: فهم القهوة | D54: فرق بين طرق التحضير في دقيقة. | E54: بانتظار مراجعة كاتب ناطق

Sheet المؤشرات
A1: المؤشر | B1: المنصة | C1: طريقة القياس | D1: القيمة المستهدفة
A2: زيارات الملف الشخصي | B2: إنستجرام | C2: إحصاءات الحساب | D2: [بعد خط أساس الأسبوع 4]
A3: الحفظ والمشاركة | B3: إنستجرام | C3: إحصاءات المنشور | D3: [بعد خط أساس الأسبوع 4]
A4: مشاهدات الريلز | B4: إنستجرام | C4: إحصاءات الريل | D4: [بعد خط أساس الأسبوع 4]
A5: وصول المنشورات المحلية | B5: فيسبوك | C5: إحصاءات الصفحة | D5: [بعد خط أساس الأسبوع 4]
A6: مشاهدات الملف والاتجاهات والمكالمات | B6: خرائط جوجل | C6: إحصاءات الملف | D6: [بعد الافتتاح]
A7: بدء محادثات واتساب | B7: واتساب | C7: عدّاد يدوي أو أداة | D7: [بعد الافتتاح]
A8: حضور الافتتاح التجريبي | B8: ميداني | C8: قائمة حضور | D8: [حسب الدعوات]
A9: استرداد العرض | B9: ميداني | C9: كود أو بطاقة | D9: [بعد تأكيد العرض]

Sheet الاعتماد
A1: الخطوة | B1: المسؤول | C1: المدة المقترحة | D1: الملاحظات
A2: مسودة المحتوى | B2: المسوّق | C2: 1 يوم | D2: نص وفكرة
A3: مراجعة اللغة | B3: كاتب ناطق | C3: 1 يوم | D3: اللهجة المصرية
A4: اعتماد المالك | B4: المالك | C4: 24 إلى 48 ساعة | D4: يُحدد من هو المعتمد [مطلوب]
A5: الجدولة | B5: المسوّق | C5: نفس اليوم | D5: بعد الاعتماد فقط
A6: المتابعة والرد | B6: مسؤول المجتمع | C6: يوميًا | D6: في نفس يوم النشر

Sheet بنود مفتوحة
A1: البند | B1: لماذا يهم | C1: المسؤول | D1: الحالة
A2: المنيو والأسعار | B2: محتوى المنتجات | C2: المالك | D2: مفتوح
A3: موعد الافتتاح | B3: ضبط التقويم | C3: المالك | D3: مفتوح
A4: العنوان والهاتف | B4: الخرائط والاتجاهات | C4: المالك | D4: مفتوح
A5: حسابات السوشيال | B5: نشر ومراجعة | C5: المالك | D5: مفتوح
A6: عرض الافتتاح المؤكد | B6: محتوى العروض | C6: المالك | D6: مفتوح
A7: مصدر البن | B7: محتوى الحرفة | C7: المالك | D7: مفتوح
A8: موافقات التصوير | B8: خصوصية | C8: المسوّق | D8: مفتوح
A9: مراجعة اللغة | B9: جودة الكابشن | C9: كاتب ناطق | D9: مفتوح
